<!DOCTYPE html>
<html lang="en">
<head>
	<meta charset="UTF-8">
	<title>Promise.all()</title>
</head>
<body>
	<script type="text/javascript">
		const promise = new Promise((resolve,reject)=>{
			resolve('hello');
		})
		.then(result => result)
		.catch(e=>e);

		const promise2 = new Promise((resolve,reject)=>{
			throw new Error('报错了');
		})
		.then(result => result)
		.catch(e=>e);

		Promise.all([promise,promise2])
		.then(result=>console.log(result))
		.catch(e=>console.log(e));						//["hello", Error: 报错了]
		// 上面代码中，p1会resolved，p2首先会rejected，但是p2有自己的catch方法，该方法返回的是一个新的 Promise 实例，p2指向的实际上是这个实例。该实例执行完catch方法后，也会变成resolved，导致Promise.all()方法参数里面的两个实例都会resolved，因此会调用then方法指定的回调函数，而不会调用catch方法指定的回调函数。

	</script>
</body>
</html>